<?xml version="1.0" encoding="utf-8"?>
<!-- This URDF was automatically created by SolidWorks to URDF Exporter! Originally created by Stephen Brawner (brawner@gmail.com) 
     Commit Version: 1.5.1-0-g916b5db  Build Version: 1.5.7152.31018
     For more information, please see http://wiki.ros.org/sw_urdf_exporter -->
<robot
  name="A001_full_assem">
  <link
    name="body">
    <inertial>
      <origin
        xyz="-0.000174571226719436 9.06240092126826E-18 -0.000317634800286892"
        rpy="0 0 0" />
      <mass
        value="3.53421059124483" />
      <inertia
        ixx="0.0082468084514557"
        ixy="-7.60265025238063E-17"
        ixz="2.35072626787776E-05"
        iyy="0.0288201000684999"
        iyz="-1.52363759666145E-17"
        izz="0.0334951886292465" />
    </inertial>
    <visual>
      <origin
        xyz="0 0 0"
        rpy="0 0 0" />
      <geometry>
        <mesh
          filename="package://A001_full_assem/meshes/body.STL" />
      </geometry>
      <material
        name="">
        <color
          rgba="0.792156862745098 0.819607843137255 0.933333333333333 1" />
      </material>
    </visual>
    <collision>
      <origin
        xyz="0 0 0"
        rpy="0 0 0" />
      <geometry>
        <mesh
          filename="package://A001_full_assem/meshes/body.STL" />
      </geometry>
    </collision>
  </link>
  <link
    name="front_left_coxa">
    <inertial>
      <origin
        xyz="0.0101571676911325 1.29074873629562E-18 0.0360475703553503"
        rpy="0 0 0" />
      <mass
        value="0.357956566838238" />
      <inertia
        ixx="0.000267566341044879"
        ixy="-9.96989892557635E-21"
        ixz="2.38105573028357E-06"
        iyy="0.000318616541927675"
        iyz="1.14121597855963E-20"
        izz="0.000314891505706399" />
    </inertial>
    <visual>
      <origin
        xyz="0 0 0"
        rpy="0 0 0" />
      <geometry>
        <mesh
          filename="package://A001_full_assem/meshes/front_left_coxa.STL" />
      </geometry>
      <material
        name="">
        <color
          rgba="0.792156862745098 0.819607843137255 0.933333333333333 1" />
      </material>
    </visual>
    <collision>
      <origin
        xyz="0 0 0"
        rpy="0 0 0" />
      <geometry>
        <mesh
          filename="package://A001_full_assem/meshes/front_left_coxa.STL" />
      </geometry>
    </collision>
  </link>
  <joint
    name="front_left_j1"
    type="continuous">
    <origin
      xyz="0.155 0.04 0"
      rpy="1.5708 0 1.5708" />
    <parent
      link="body" />
    <child
      link="front_left_coxa" />
    <axis
      xyz="0 0 1" />
  </joint>
  <link
    name="front_left_femur">
    <inertial>
      <origin
        xyz="0.0540403586792016 -0.000392932947434519 0.000209269982925628"
        rpy="0 0 0" />
      <mass
        value="0.221779515725082" />
      <inertia
        ixx="9.24043033879767E-05"
        ixy="5.40703887251772E-07"
        ixz="7.02697694701529E-06"
        iyy="0.000826603782824903"
        iyz="-1.82367235893873E-08"
        izz="0.000859693992619264" />
    </inertial>
    <visual>
      <origin
        xyz="0 0 0"
        rpy="0 0 0" />
      <geometry>
        <mesh
          filename="package://A001_full_assem/meshes/front_left_femur.STL" />
      </geometry>
      <material
        name="">
        <color
          rgba="0.792156862745098 0.819607843137255 0.933333333333333 1" />
      </material>
    </visual>
    <collision>
      <origin
        xyz="0 0 0"
        rpy="0 0 0" />
      <geometry>
        <mesh
          filename="package://A001_full_assem/meshes/front_left_femur.STL" />
      </geometry>
    </collision>
  </link>
  <joint
    name="front_left_j2"
    type="continuous">
    <origin
      xyz="0.071 0 0.038"
      rpy="0 1.5708 0" />
    <parent
      link="front_left_coxa" />
    <child
      link="front_left_femur" />
    <axis
      xyz="0 0 1" />
  </joint>
  <link
    name="front_left_tibia">
    <inertial>
      <origin
        xyz="0.0769737322157676 -0.000161721808717277 1.38777878078145E-17"
        rpy="0 0 0" />
      <mass
        value="0.0767264004240441" />
      <inertia
        ixx="5.98334796474589E-06"
        ixy="-2.28166947954325E-07"
        ixz="-3.56496599667045E-21"
        iyy="0.000243227038063636"
        iyz="1.71305728065961E-13"
        izz="0.000243965339910109" />
    </inertial>
    <visual>
      <origin
        xyz="0 0 0"
        rpy="0 0 0" />
      <geometry>
        <mesh
          filename="package://A001_full_assem/meshes/front_left_tibia.STL" />
      </geometry>
      <material
        name="">
        <color
          rgba="0.792156862745098 0.819607843137255 0.933333333333333 1" />
      </material>
    </visual>
    <collision>
      <origin
        xyz="0 0 0"
        rpy="0 0 0" />
      <geometry>
        <mesh
          filename="package://A001_full_assem/meshes/front_left_tibia.STL" />
      </geometry>
    </collision>
  </link>
  <joint
    name="front_left_j3"
    type="continuous">
    <origin
      xyz="0.16 0 0"
      rpy="0 0 -1.5708" />
    <parent
      link="front_left_femur" />
    <child
      link="front_left_tibia" />
    <axis
      xyz="0 0 1" />
  </joint>
  <link
    name="front_right_coxa">
    <inertial>
      <origin
        xyz="0.0101571676911324 -1.93167383400936E-18 0.0360475703553503"
        rpy="0 0 0" />
      <mass
        value="0.357956566838237" />
      <inertia
        ixx="0.000267566341044878"
        ixy="1.77544371288973E-20"
        ixz="2.3810557302835E-06"
        iyy="0.000318616541927675"
        iyz="-1.22879906266724E-20"
        izz="0.000314891505706399" />
    </inertial>
    <visual>
      <origin
        xyz="0 0 0"
        rpy="0 0 0" />
      <geometry>
        <mesh
          filename="package://A001_full_assem/meshes/front_right_coxa.STL" />
      </geometry>
      <material
        name="">
        <color
          rgba="0.792156862745098 0.819607843137255 0.933333333333333 1" />
      </material>
    </visual>
    <collision>
      <origin
        xyz="0 0 0"
        rpy="0 0 0" />
      <geometry>
        <mesh
          filename="package://A001_full_assem/meshes/front_right_coxa.STL" />
      </geometry>
    </collision>
  </link>
  <joint
    name="front_right_j1"
    type="continuous">
    <origin
      xyz="0.155 -0.0399999999999995 0"
      rpy="-1.5707963267949 0 -1.57079632679489" />
    <parent
      link="body" />
    <child
      link="front_right_coxa" />
    <axis
      xyz="0 0 1" />
  </joint>
  <link
    name="front_right_femur">
    <inertial>
      <origin
        xyz="0.0540403586792016 0.000392932947434331 0.000209269982925558"
        rpy="0 0 0" />
      <mass
        value="0.221779515725082" />
      <inertia
        ixx="9.24043033879767E-05"
        ixy="-5.4070388724918E-07"
        ixz="7.02697694701628E-06"
        iyy="0.000826603782824904"
        iyz="1.82367235893569E-08"
        izz="0.000859693992619265" />
    </inertial>
    <visual>
      <origin
        xyz="0 0 0"
        rpy="0 0 0" />
      <geometry>
        <mesh
          filename="package://A001_full_assem/meshes/front_right_femur.STL" />
      </geometry>
      <material
        name="">
        <color
          rgba="0.792156862745098 0.819607843137255 0.933333333333333 1" />
      </material>
    </visual>
    <collision>
      <origin
        xyz="0 0 0"
        rpy="0 0 0" />
      <geometry>
        <mesh
          filename="package://A001_full_assem/meshes/front_right_femur.STL" />
      </geometry>
    </collision>
  </link>
  <joint
    name="front_right_j2"
    type="continuous">
    <origin
      xyz="0.071 0 0.038"
      rpy="0 1.5707963267949 0" />
    <parent
      link="front_right_coxa" />
    <child
      link="front_right_femur" />
    <axis
      xyz="0 0 1" />
  </joint>
  <link
    name="front_right_tibia">
    <inertial>
      <origin
        xyz="0.0769737291485542 0.000161721337977823 4.75390005139076E-11"
        rpy="0 0 0" />
      <mass
        value="0.0767263959082595" />
      <inertia
        ixx="5.98334790928996E-06"
        ixy="2.28168970537447E-07"
        ixz="-1.24223191388862E-13"
        iyy="0.000243227025333368"
        iyz="7.74749005378918E-14"
        izz="0.000243965326667764" />
    </inertial>
    <visual>
      <origin
        xyz="0 0 0"
        rpy="0 0 0" />
      <geometry>
        <mesh
          filename="package://A001_full_assem/meshes/front_right_tibia.STL" />
      </geometry>
      <material
        name="">
        <color
          rgba="0.792156862745098 0.819607843137255 0.933333333333333 1" />
      </material>
    </visual>
    <collision>
      <origin
        xyz="0 0 0"
        rpy="0 0 0" />
      <geometry>
        <mesh
          filename="package://A001_full_assem/meshes/front_right_tibia.STL" />
      </geometry>
    </collision>
  </link>
  <joint
    name="front_right_j3"
    type="continuous">
    <origin
      xyz="0.16 0 0"
      rpy="0 0 1.5708" />
    <parent
      link="front_right_femur" />
    <child
      link="front_right_tibia" />
    <axis
      xyz="0 0 1" />
  </joint>
  <link
    name="back_left_coxa">
    <inertial>
      <origin
        xyz="0.0101571676911324 -1.39680278333714E-18 0.0360475703553502"
        rpy="0 0 0" />
      <mass
        value="0.357956566838238" />
      <inertia
        ixx="0.000267566341044879"
        ixy="-6.75277430057797E-21"
        ixz="2.38105573028354E-06"
        iyy="0.000318616541927675"
        iyz="-1.19816855782472E-22"
        izz="0.000314891505706399" />
    </inertial>
    <visual>
      <origin
        xyz="0 0 0"
        rpy="0 0 0" />
      <geometry>
        <mesh
          filename="package://A001_full_assem/meshes/back_left_coxa.STL" />
      </geometry>
      <material
        name="">
        <color
          rgba="0.792156862745098 0.819607843137255 0.933333333333333 1" />
      </material>
    </visual>
    <collision>
      <origin
        xyz="0 0 0"
        rpy="0 0 0" />
      <geometry>
        <mesh
          filename="package://A001_full_assem/meshes/back_left_coxa.STL" />
      </geometry>
    </collision>
  </link>
  <joint
    name="back_left_j1"
    type="continuous">
    <origin
      xyz="-0.155 0.04 0"
      rpy="-1.5708 0 1.5708" />
    <parent
      link="body" />
    <child
      link="back_left_coxa" />
    <axis
      xyz="0 0 1" />
  </joint>
  <link
    name="back_left_femur">
    <inertial>
      <origin
        xyz="0.0540403586792017 -0.00039293294743452 0.000209269982925614"
        rpy="0 0 0" />
      <mass
        value="0.221779515725082" />
      <inertia
        ixx="9.24043033879768E-05"
        ixy="5.4070388725173E-07"
        ixz="7.02697694701545E-06"
        iyy="0.000826603782824904"
        iyz="-1.82367235893669E-08"
        izz="0.000859693992619265" />
    </inertial>
    <visual>
      <origin
        xyz="0 0 0"
        rpy="0 0 0" />
      <geometry>
        <mesh
          filename="package://A001_full_assem/meshes/back_left_femur.STL" />
      </geometry>
      <material
        name="">
        <color
          rgba="0.792156862745098 0.819607843137255 0.933333333333333 1" />
      </material>
    </visual>
    <collision>
      <origin
        xyz="0 0 0"
        rpy="0 0 0" />
      <geometry>
        <mesh
          filename="package://A001_full_assem/meshes/back_left_femur.STL" />
      </geometry>
    </collision>
  </link>
  <joint
    name="back_left_j2"
    type="continuous">
    <origin
      xyz="0.071 0 0.0380000000000001"
      rpy="0 -1.5707963267949 0" />
    <parent
      link="back_left_coxa" />
    <child
      link="back_left_femur" />
    <axis
      xyz="0 0 1" />
  </joint>
  <link
    name="back_left_tibia">
    <inertial>
      <origin
        xyz="0.0769737322157677 -0.000161721808717208 1.38777878078145E-17"
        rpy="0 0 0" />
      <mass
        value="0.0767264004240441" />
      <inertia
        ixx="5.98334796474589E-06"
        ixy="-2.28166947954268E-07"
        ixz="7.74731472289028E-21"
        iyy="0.000243227038063636"
        iyz="1.71305722685129E-13"
        izz="0.000243965339910108" />
    </inertial>
    <visual>
      <origin
        xyz="0 0 0"
        rpy="0 0 0" />
      <geometry>
        <mesh
          filename="package://A001_full_assem/meshes/back_left_tibia.STL" />
      </geometry>
      <material
        name="">
        <color
          rgba="0.792156862745098 0.819607843137255 0.933333333333333 1" />
      </material>
    </visual>
    <collision>
      <origin
        xyz="0 0 0"
        rpy="0 0 0" />
      <geometry>
        <mesh
          filename="package://A001_full_assem/meshes/back_left_tibia.STL" />
      </geometry>
    </collision>
  </link>
  <joint
    name="back_left_j3"
    type="continuous">
    <origin
      xyz="0.16 0 0"
      rpy="0 0 1.5707963267949" />
    <parent
      link="back_left_femur" />
    <child
      link="back_left_tibia" />
    <axis
      xyz="0 0 1" />
  </joint>
  <link
    name="back_right_coxa">
    <inertial>
      <origin
        xyz="0.0101571676911325 5.20370394582273E-19 0.0360475703553502"
        rpy="0 0 0" />
      <mass
        value="0.357956566838238" />
      <inertia
        ixx="0.000267566341044879"
        ixy="-1.13816965091098E-20"
        ixz="2.3810557302836E-06"
        iyy="0.000318616541927676"
        iyz="8.91515003141497E-21"
        izz="0.000314891505706399" />
    </inertial>
    <visual>
      <origin
        xyz="0 0 0"
        rpy="0 0 0" />
      <geometry>
        <mesh
          filename="package://A001_full_assem/meshes/back_right_coxa.STL" />
      </geometry>
      <material
        name="">
        <color
          rgba="0.792156862745098 0.819607843137255 0.933333333333333 1" />
      </material>
    </visual>
    <collision>
      <origin
        xyz="0 0 0"
        rpy="0 0 0" />
      <geometry>
        <mesh
          filename="package://A001_full_assem/meshes/back_right_coxa.STL" />
      </geometry>
    </collision>
  </link>
  <joint
    name="back_right_j1"
    type="continuous">
    <origin
      xyz="-0.155 -0.0400000000000005 0"
      rpy="1.5707963267949 0 -1.57079632679489" />
    <parent
      link="body" />
    <child
      link="back_right_coxa" />
    <axis
      xyz="0 0 1" />
  </joint>
  <link
    name="back_right_femur">
    <inertial>
      <origin
        xyz="0.0540403586792017 0.000392932947434332 0.000209269982925558"
        rpy="0 0 0" />
      <mass
        value="0.221779515725082" />
      <inertia
        ixx="9.24043033879769E-05"
        ixy="-5.40703887249155E-07"
        ixz="7.02697694701625E-06"
        iyy="0.000826603782824905"
        iyz="1.82367235893639E-08"
        izz="0.000859693992619266" />
    </inertial>
    <visual>
      <origin
        xyz="0 0 0"
        rpy="0 0 0" />
      <geometry>
        <mesh
          filename="package://A001_full_assem/meshes/back_right_femur.STL" />
      </geometry>
      <material
        name="">
        <color
          rgba="0.792156862745098 0.819607843137255 0.933333333333333 1" />
      </material>
    </visual>
    <collision>
      <origin
        xyz="0 0 0"
        rpy="0 0 0" />
      <geometry>
        <mesh
          filename="package://A001_full_assem/meshes/back_right_femur.STL" />
      </geometry>
    </collision>
  </link>
  <joint
    name="back_right_j2"
    type="continuous">
    <origin
      xyz="0.071 0 0.038"
      rpy="0 -1.5707963267949 0" />
    <parent
      link="back_right_coxa" />
    <child
      link="back_right_femur" />
    <axis
      xyz="0 0 1" />
  </joint>
  <link
    name="back_right_tibia">
    <inertial>
      <origin
        xyz="0.0769737291485542 0.000161721337977927 4.75389311249685E-11"
        rpy="0 0 0" />
      <mass
        value="0.0767263959082593" />
      <inertia
        ixx="5.98334790928995E-06"
        ixy="2.28168970537263E-07"
        ixz="-1.24223241897431E-13"
        iyy="0.000243227025333368"
        iyz="7.7474888757983E-14"
        izz="0.000243965326667764" />
    </inertial>
    <visual>
      <origin
        xyz="0 0 0"
        rpy="0 0 0" />
      <geometry>
        <mesh
          filename="package://A001_full_assem/meshes/back_right_tibia.STL" />
      </geometry>
      <material
        name="">
        <color
          rgba="0.792156862745098 0.819607843137255 0.933333333333333 1" />
      </material>
    </visual>
    <collision>
      <origin
        xyz="0 0 0"
        rpy="0 0 0" />
      <geometry>
        <mesh
          filename="package://A001_full_assem/meshes/back_right_tibia.STL" />
      </geometry>
    </collision>
  </link>
  <joint
    name="back_right_j3"
    type="continuous">
    <origin
      xyz="0.16 0 0"
      rpy="0 0 -1.5707963267949" />
    <parent
      link="back_right_femur" />
    <child
      link="back_right_tibia" />
    <axis
      xyz="0 0 1" />
  </joint>
</robot>